[2024-12-29T08:49:53.110+0000] {local_task_job_runner.py:123} INFO - ::group::Pre task execution logs
[2024-12-29T08:49:53.126+0000] {taskinstance.py:2613} INFO - Dependencies all met for dep_context=non-requeueable deps ti=<TaskInstance: churn_prediction_pipeline.data_ingestion manual__2024-12-29T08:49:47.140068+00:00 [queued]>
[2024-12-29T08:49:53.135+0000] {taskinstance.py:2613} INFO - Dependencies all met for dep_context=requeueable deps ti=<TaskInstance: churn_prediction_pipeline.data_ingestion manual__2024-12-29T08:49:47.140068+00:00 [queued]>
[2024-12-29T08:49:53.136+0000] {taskinstance.py:2866} INFO - Starting attempt 1 of 2
[2024-12-29T08:49:53.146+0000] {taskinstance.py:2889} INFO - Executing <Task(PythonOperator): data_ingestion> on 2024-12-29 08:49:47.140068+00:00
[2024-12-29T08:49:53.159+0000] {standard_task_runner.py:104} INFO - Running: ['***', 'tasks', 'run', 'churn_prediction_pipeline', 'data_ingestion', 'manual__2024-12-29T08:49:47.140068+00:00', '--job-id', '2', '--raw', '--subdir', 'DAGS_FOLDER/churn_prediction_dag.py', '--cfg-path', '/tmp/tmp09nrpqbz']
[2024-12-29T08:49:53.162+0000] {standard_task_runner.py:105} INFO - Job 2: Subtask data_ingestion
[2024-12-29T08:49:53.163+0000] {logging_mixin.py:190} WARNING - /home/***/.local/lib/python3.12/site-packages/***/task/task_runner/standard_task_runner.py:70 DeprecationWarning: This process (pid=119) is multi-threaded, use of fork() may lead to deadlocks in the child.
[2024-12-29T08:49:53.163+0000] {standard_task_runner.py:72} INFO - Started process 168 to run task
[2024-12-29T08:49:53.212+0000] {task_command.py:467} INFO - Running <TaskInstance: churn_prediction_pipeline.data_ingestion manual__2024-12-29T08:49:47.140068+00:00 [running]> on host f3811aaed405
[2024-12-29T08:49:53.284+0000] {taskinstance.py:3132} INFO - Exporting env vars: AIRFLOW_CTX_DAG_OWNER='***' AIRFLOW_CTX_DAG_ID='churn_prediction_pipeline' AIRFLOW_CTX_TASK_ID='data_ingestion' AIRFLOW_CTX_EXECUTION_DATE='2024-12-29T08:49:47.140068+00:00' AIRFLOW_CTX_TRY_NUMBER='1' AIRFLOW_CTX_DAG_RUN_ID='manual__2024-12-29T08:49:47.140068+00:00'
[2024-12-29T08:49:53.285+0000] {taskinstance.py:731} INFO - ::endgroup::
[2024-12-29T08:49:53.312+0000] {taskinstance.py:3311} ERROR - Task failed with exception
Traceback (most recent call last):
  File "/opt/airflow/dags/churn_prediction_dag.py", line 45, in data_ingestion_task
    data_ingestion_config = DataIngestionConfig(training_pipeline_config)
                            ^^^^^^^^^^^^^^^^^^^^^^^^^^^^^^^^^^^^^^^^^^^^^
  File "/opt/airflow/ChurnPrediction/entity/config_entity.py", line 21, in __init__
    self.feature_store_file_path:str=os.path.join(self.data_ingestion_dir,training_pipeline.DATA_INGESTION_FEATURE_STORE_DIR,
                                     ^^^^^^^^^^^^^^^^^^^^^^^^^^^^^^^^^^^^^^^^^^^^^^^^^^^^^^^^^^^^^^^^^^^^^^^^^^^^^^^^^^^^^^^^
  File "<frozen posixpath>", line 90, in join
  File "<frozen genericpath>", line 164, in _check_arg_types
TypeError: join() argument must be str, bytes, or os.PathLike object, not 'NoneType'

During handling of the above exception, another exception occurred:

Traceback (most recent call last):
  File "/home/airflow/.local/lib/python3.12/site-packages/airflow/models/taskinstance.py", line 767, in _execute_task
    result = _execute_callable(context=context, **execute_callable_kwargs)
             ^^^^^^^^^^^^^^^^^^^^^^^^^^^^^^^^^^^^^^^^^^^^^^^^^^^^^^^^^^^^^
  File "/home/airflow/.local/lib/python3.12/site-packages/airflow/models/taskinstance.py", line 733, in _execute_callable
    return ExecutionCallableRunner(
           ^^^^^^^^^^^^^^^^^^^^^^^^
  File "/home/airflow/.local/lib/python3.12/site-packages/airflow/utils/operator_helpers.py", line 252, in run
    return self.func(*args, **kwargs)
           ^^^^^^^^^^^^^^^^^^^^^^^^^^
  File "/home/airflow/.local/lib/python3.12/site-packages/airflow/models/baseoperator.py", line 422, in wrapper
    return func(self, *args, **kwargs)
           ^^^^^^^^^^^^^^^^^^^^^^^^^^^
  File "/home/airflow/.local/lib/python3.12/site-packages/airflow/operators/python.py", line 238, in execute
    return_value = self.execute_callable()
                   ^^^^^^^^^^^^^^^^^^^^^^^
  File "/home/airflow/.local/lib/python3.12/site-packages/airflow/operators/python.py", line 256, in execute_callable
    return runner.run(*self.op_args, **self.op_kwargs)
           ^^^^^^^^^^^^^^^^^^^^^^^^^^^^^^^^^^^^^^^^^^^
  File "/home/airflow/.local/lib/python3.12/site-packages/airflow/utils/operator_helpers.py", line 252, in run
    return self.func(*args, **kwargs)
           ^^^^^^^^^^^^^^^^^^^^^^^^^^
  File "/opt/airflow/dags/churn_prediction_dag.py", line 50, in data_ingestion_task
    raise ChurnPredictionException(e, sys)
ChurnPrediction.exception.exception.ChurnPredictionException: <exception str() failed>
[2024-12-29T08:49:53.331+0000] {taskinstance.py:1225} INFO - Marking task as UP_FOR_RETRY. dag_id=churn_prediction_pipeline, task_id=data_ingestion, run_id=manual__2024-12-29T08:49:47.140068+00:00, execution_date=20241229T084947, start_date=20241229T084953, end_date=20241229T084953
[2024-12-29T08:49:53.341+0000] {taskinstance.py:340} INFO - ::group::Post task execution logs
[2024-12-29T08:49:53.342+0000] {standard_task_runner.py:124} ERROR - Failed to execute job 2 for task data_ingestion (name 'atr' is not defined; 168)
Traceback (most recent call last):
  File "/opt/airflow/dags/churn_prediction_dag.py", line 45, in data_ingestion_task
    data_ingestion_config = DataIngestionConfig(training_pipeline_config)
                            ^^^^^^^^^^^^^^^^^^^^^^^^^^^^^^^^^^^^^^^^^^^^^
  File "/opt/airflow/ChurnPrediction/entity/config_entity.py", line 21, in __init__
    self.feature_store_file_path:str=os.path.join(self.data_ingestion_dir,training_pipeline.DATA_INGESTION_FEATURE_STORE_DIR,
                                     ^^^^^^^^^^^^^^^^^^^^^^^^^^^^^^^^^^^^^^^^^^^^^^^^^^^^^^^^^^^^^^^^^^^^^^^^^^^^^^^^^^^^^^^^
  File "<frozen posixpath>", line 90, in join
  File "<frozen genericpath>", line 164, in _check_arg_types
TypeError: join() argument must be str, bytes, or os.PathLike object, not 'NoneType'

During handling of the above exception, another exception occurred:

Traceback (most recent call last):
  File "/home/airflow/.local/lib/python3.12/site-packages/airflow/models/taskinstance.py", line 273, in _run_raw_task
    TaskInstance._execute_task_with_callbacks(
  File "/home/airflow/.local/lib/python3.12/site-packages/airflow/models/taskinstance.py", line 3159, in _execute_task_with_callbacks
    result = self._execute_task(context, task_orig)
             ^^^^^^^^^^^^^^^^^^^^^^^^^^^^^^^^^^^^^^
  File "/home/airflow/.local/lib/python3.12/site-packages/airflow/models/taskinstance.py", line 3183, in _execute_task
    return _execute_task(self, context, task_orig)
           ^^^^^^^^^^^^^^^^^^^^^^^^^^^^^^^^^^^^^^^
  File "/home/airflow/.local/lib/python3.12/site-packages/airflow/models/taskinstance.py", line 767, in _execute_task
    result = _execute_callable(context=context, **execute_callable_kwargs)
             ^^^^^^^^^^^^^^^^^^^^^^^^^^^^^^^^^^^^^^^^^^^^^^^^^^^^^^^^^^^^^
  File "/home/airflow/.local/lib/python3.12/site-packages/airflow/models/taskinstance.py", line 733, in _execute_callable
    return ExecutionCallableRunner(
           ^^^^^^^^^^^^^^^^^^^^^^^^
  File "/home/airflow/.local/lib/python3.12/site-packages/airflow/utils/operator_helpers.py", line 252, in run
    return self.func(*args, **kwargs)
           ^^^^^^^^^^^^^^^^^^^^^^^^^^
  File "/home/airflow/.local/lib/python3.12/site-packages/airflow/models/baseoperator.py", line 422, in wrapper
    return func(self, *args, **kwargs)
           ^^^^^^^^^^^^^^^^^^^^^^^^^^^
  File "/home/airflow/.local/lib/python3.12/site-packages/airflow/operators/python.py", line 238, in execute
    return_value = self.execute_callable()
                   ^^^^^^^^^^^^^^^^^^^^^^^
  File "/home/airflow/.local/lib/python3.12/site-packages/airflow/operators/python.py", line 256, in execute_callable
    return runner.run(*self.op_args, **self.op_kwargs)
           ^^^^^^^^^^^^^^^^^^^^^^^^^^^^^^^^^^^^^^^^^^^
  File "/home/airflow/.local/lib/python3.12/site-packages/airflow/utils/operator_helpers.py", line 252, in run
    return self.func(*args, **kwargs)
           ^^^^^^^^^^^^^^^^^^^^^^^^^^
  File "/opt/airflow/dags/churn_prediction_dag.py", line 50, in data_ingestion_task
    raise ChurnPredictionException(e, sys)
ChurnPrediction.exception.exception.ChurnPredictionException: <exception str() failed>

During handling of the above exception, another exception occurred:

Traceback (most recent call last):
  File "/home/airflow/.local/lib/python3.12/site-packages/airflow/task/task_runner/standard_task_runner.py", line 117, in _start_by_fork
    ret = args.func(args, dag=self.dag)
          ^^^^^^^^^^^^^^^^^^^^^^^^^^^^^
  File "/home/airflow/.local/lib/python3.12/site-packages/airflow/cli/cli_config.py", line 49, in command
    return func(*args, **kwargs)
           ^^^^^^^^^^^^^^^^^^^^^
  File "/home/airflow/.local/lib/python3.12/site-packages/airflow/utils/cli.py", line 116, in wrapper
    return f(*args, **kwargs)
           ^^^^^^^^^^^^^^^^^^
  File "/home/airflow/.local/lib/python3.12/site-packages/airflow/cli/commands/task_command.py", line 483, in task_run
    task_return_code = _run_task_by_selected_method(args, _dag, ti)
                       ^^^^^^^^^^^^^^^^^^^^^^^^^^^^^^^^^^^^^^^^^^^^
  File "/home/airflow/.local/lib/python3.12/site-packages/airflow/cli/commands/task_command.py", line 256, in _run_task_by_selected_method
    return _run_raw_task(args, ti)
           ^^^^^^^^^^^^^^^^^^^^^^^
  File "/home/airflow/.local/lib/python3.12/site-packages/airflow/cli/commands/task_command.py", line 341, in _run_raw_task
    return ti._run_raw_task(
           ^^^^^^^^^^^^^^^^^
  File "/home/airflow/.local/lib/python3.12/site-packages/airflow/utils/session.py", line 97, in wrapper
    return func(*args, session=session, **kwargs)
           ^^^^^^^^^^^^^^^^^^^^^^^^^^^^^^^^^^^^^^
  File "/home/airflow/.local/lib/python3.12/site-packages/airflow/models/taskinstance.py", line 3005, in _run_raw_task
    return _run_raw_task(
           ^^^^^^^^^^^^^^
  File "/home/airflow/.local/lib/python3.12/site-packages/airflow/models/taskinstance.py", line 336, in _run_raw_task
    ti.handle_failure(e, test_mode, context, session=session)
  File "/home/airflow/.local/lib/python3.12/site-packages/airflow/utils/session.py", line 94, in wrapper
    return func(*args, **kwargs)
           ^^^^^^^^^^^^^^^^^^^^^
  File "/home/airflow/.local/lib/python3.12/site-packages/airflow/models/taskinstance.py", line 3428, in handle_failure
    _handle_failure(
  File "/home/airflow/.local/lib/python3.12/site-packages/airflow/utils/session.py", line 94, in wrapper
    return func(*args, **kwargs)
           ^^^^^^^^^^^^^^^^^^^^^
  File "/home/airflow/.local/lib/python3.12/site-packages/airflow/api_internal/internal_api_call.py", line 166, in wrapper
    return func(*args, **kwargs)
           ^^^^^^^^^^^^^^^^^^^^^
  File "/home/airflow/.local/lib/python3.12/site-packages/airflow/models/taskinstance.py", line 1248, in _handle_failure
    span.set_attribute("error_msg", str(error))
                                    ^^^^^^^^^^
  File "/opt/airflow/ChurnPrediction/exception/exception.py", line 13, in __str__
    return f"Error: {atr(self.error_message)} at {self.filename} line {self.lineno}"
                     ^^^
NameError: name 'atr' is not defined. Did you mean: 'str'?
[2024-12-29T08:49:53.379+0000] {local_task_job_runner.py:266} INFO - Task exited with return code 1
[2024-12-29T08:49:53.396+0000] {taskinstance.py:3895} INFO - 0 downstream tasks scheduled from follow-on schedule check
[2024-12-29T08:49:53.398+0000] {local_task_job_runner.py:245} INFO - ::endgroup::
